Workbook
Name IQ_CH: 110000
Name IQ_CQ: 5000
Name IQ_CY: 10000
Name IQ_DAILY: 500000
Name IQ_FH: 100000
Name IQ_FQ: 500
Name IQ_FY: 1000
Name IQ_LTM: 2000
Name IQ_MONTH: 15000
Name IQ_NTM: 6000
Name IQ_WEEK: 50000
Name IQ_YTD: 3000

Sheet Firms
A1: Firm Name | B1: Type | C1: State | D1: City | E1: Website | F1: US Investments | G1: Revenue Min ($M) | H1: Revenue Max ($M) | I1: EBITDA Min ($M) | J1: EBITDA Max ($M) | K1: EV Min ($M) | L1: EV Max ($M) | M1: Check Min ($M) | N1: Check Max ($M) | O1: Deal Types | P1: Sector Tier 1 | Q1: Sector Tier 2 | R1: Sector Tier 3 | S1: Exclusions | T1: AUM ($M) | U1: Activity | V1: Last Deal | W1: Fund Name | X1: Confidence | Y1: Needs Review | Z1: Last Checked | AA1: Status | AB1: Notes
A2: 26North Partners LP | B2: PE | E2: https://www.26n.com | F2: primarily | O2: Buyout | P2: Generalist, Technology | T2: 5900.0 | U2: Active | V2: 2026-03-31 | W2: 26North Inaugural Private Equity Fund | X2: Medium | Y2: No | Z2: 2026-06-07 | AA2: complete | AB2: Seeded from CapIQ export. Numeric fields are regex first-pass — crawler will confirm. capiq_description preserved for AI extraction fallback. | [extractor] 26North Partners LP is a next-generation alternatives platform founded by Josh Harris, with strategies spanning private equity (buyouts), direct lending, investment grade alpha (credit), and insurance. Raised $5.9B for inaugural PE fund in April 2026, surpassing $4B target (Bloomberg headline references $6B). Most recent deal: acquisition of Intermedia (cloud communications firm), announced March 31, 2026. HQ city/state not confirmed from source pages. Sector focus is generalist with a notable technology deal (Intermedia). Press release PDF found: https://www.26n.com/~/media/Files/T/twentysix-north/Universal/news/26-north-raises-5-9-billion-for-inaugural-private-equity-fund-surpassing-4-billion-target.pdf — not parsed. Deal PDF found: https://www.26n.com/~/media/Files/T/twentysix-north/Universal/news/26-north-to-acquire-leading-cloud-communications-firm-intermedia.pdf — not parsed. No explicit investment criteria (revenue, EBITDA, check size, EV thresholds) found on site. | AC2: =COUNTIF(Sheet1!$A$1:$A$50,Firms!A2) -> 0
A3: 4x4 Capital, LLC | B3: Other | E3: https://4x4capital.com | P3: Consumer | U3: Active | X3: Low | Y3: Yes | Z3: 2026-06-07 | AA3: complete | AB3: Seeded from CapIQ export. Numeric fields are regex first-pass — crawler will confirm. capiq_description preserved for AI extraction fallback. | [extractor] Strategy page provided contains only navigation menu and header HTML; no substantive investment criteria, fund details, deal types, sectors, or financial parameters are visible in the supplied content. Full page content appears truncated. Requires review of complete website pages (About, Portfolio, Team, News sections) or direct contact to extract investment criteria. | AC3: =COUNTIF(Sheet1!$A$1:$A$50,Firms!A3) -> 0
A4: A&M Capital Advisors, LP | B4: PE | C4: CT | D4: Greenwich | E4: https://www.a-mcapital.com | F4: primarily | I4: 15.0 | J4: 100.0 | K4: 75.0 | L4: 750.0 | M4: 25.0 | N4: 200.0 | O4: Buyout, Recap, Other | P4: Business Services, Healthcare, Industrials | Q4: Financial Services, Consumer, Government Services | T4: 5900.0 | U4: Active | X4: High | Y4: No | Z4: 2026-06-07 | AA4: complete | AB4: Seeded from CapIQ export. Numeric fields are regex first-pass — crawler will confirm. capiq_description preserved for AI extraction fallback. | [extractor] Multi-strategy PE firm with 4 distinct investment strategies (AMCP, AMCS, AMCE, AMCSI). Data extracted from primary investment criteria sections. AMCP flagship strategy: $3.0B AUM, $60-200M check size, $150-750M target EV, $20-100M EBITDA. AMCS secondaries: $25-75M initial checks, $100-500M EV, $15M+ underlying EBITDA. AMCE (Europe): €650M AUM (~$710M USD). AMCSI: $10-50M checks, $100M+ EV, $20M+ EBITDA. Total firm AUM stated as $5.9B. Transaction types include founder transitions, build-ups, corporate divestitures, public-to-privates, and special situations. Active investor with 170+ companies invested across 24 platforms since inception. | AC4: =COUNTIF(Sheet1!$A$1:$A$50,Firms!A4) -> 1 | AD4: =SUBSTITUTE(AB4,"Seeded from CapIQ export. Numeric fields are regex first-pass — c","C") -> Crawler will confirm. capiq_description preserved for AI extraction fallback. | [extractor] Multi-strategy PE firm with 4 distinct investment strategies (AMCP, AMCS, AMCE, AMCSI). Data extracted from primary investment criteria sections. AMCP flagship strategy: $3.0B AUM, $60-200M check size, $150-750M target EV, $20-100M EBITDA. AMCS secondaries: $25-75M initial checks, $100-500M EV, $15M+ underlying EBITDA. AMCE (Europe): €650M AUM (~$710M USD). AMCSI: $10-50M checks, $100M+ EV, $20M+ EBITDA. Total firm AUM stated as $5.9B. Transaction types include founder transitions, build-ups, corporate divestitures, public-to-privates, and special situations. Active investor with 170+ companies invested across 24 platforms since inception.
A5: AAVIN Private Equity Advisors | B5: PE | C5: IA | D5: Cedar Rapids | E5: https://www.aavin.com | F5: primarily | G5: 5.0 | H5: 50.0 | I5: 1.5 | J5: 5.0 | O5: Buyout, Recap | P5: Generalist | T5: 330.0 | U5: Active | V5: 2022 | X5: High | Y5: No | Z5: 2026-06-07 | AA5: complete | AB5: Seeded from CapIQ export. Numeric fields are regex first-pass — crawler will confirm. capiq_description preserved for AI extraction fallback. | [extractor] Explicit investment criteria found on website. Founded 1999, managing lower-middle market buyouts and recaps of founder/family-owned businesses. 50+ years of legacy (predecessor organizations). 300+ completed investments. Focus on underserved geographies in Middle America with particular emphasis on succession planning. SBIC licensee. No specific fund vintage or AUM disclosed. Portfolio and recent exits sections referenced but not detailed in source. | AC5: =COUNTIF(Sheet1!$A$1:$A$50,Firms!A5) -> 0
A6: AE Industrial Partners, LP | B6: PE | C6: FL | D6: Boca Raton | E6: https://www.aeroequity.com | F6: true | O6: Buyout, Minority | P6: Industrials, Technology | U6: Active | V6: 2025-06-01 | X6: Medium | Y6: No | Z6: 2026-06-07 | AA6: complete | AB6: Seeded from CapIQ export. Numeric fields are regex first-pass — crawler will confirm. capiq_description preserved for AI extraction fallback. | [extractor] AE Industrial Partners is a PE firm focused on aerospace, national security, and industrial services. Founded 2015. 30+ platform companies and 80+ minority/add-on investments completed. Two PDFs available but not parsed: 2025 Year In Review (https://www.aeroequity.com/wp-content/uploads/AE-Industrial-Partners-2025-Year-In-Review.pdf) and Fact Sheet April 2026 (https://www.aeroequity.com/wp-content/uploads/AE-Industrial-Fact-Sheet-April-2026.pdf). Also operates AE Ventures (early-stage tech) and AEI Aerospace Leasing. Additional office in Washington, D.C. | AC6: =COUNTIF(Sheet1!$A$1:$A$50,Firms!A6) -> 1 | AD6: =SUBSTITUTE(AB6,"Seeded from CapIQ export. Numeric fields are regex first-pass — c","C") -> Crawler will confirm. capiq_description preserved for AI extraction fallback. | [extractor] AE Industrial Partners is a PE firm focused on aerospace, national security, and industrial services. Founded 2015. 30+ platform companies and 80+ minority/add-on investments completed. Two PDFs available but not parsed: 2025 Year In Review (https://www.aeroequity.com/wp-content/uploads/AE-Industrial-Partners-2025-Year-In-Review.pdf) and Fact Sheet April 2026 (https://www.aeroequity.com/wp-content/uploads/AE-Industrial-Fact-Sheet-April-2026.pdf). Also operates AE Ventures (early-stage tech) and AEI Aerospace Leasing. Additional office in Washington, D.C.
A7: AEA Investors LP | B7: PE | E7: https://www.aeainvestors.com | O7: Buyout | P7: Business Services, Consumer, Industrials | T7: 18000.0 | U7: Active | X7: Medium | Y7: No | Z7: 2026-06-07 | AA7: complete | AB7: Seeded from CapIQ export. Numeric fields are regex first-pass — crawler will confirm. capiq_description preserved for AI extraction fallback. | [extractor] AEA Investors LP is a multi-platform PE firm with four investment groups: Middle Market Private Equity, Enterprise, Elevate, and Private Debt. Pages provided show portfolio structure but no actual portfolio companies displayed (filter results empty). Firm focuses on backing founders/management teams and transforming/accelerating growth. Elevate specifically targets professional services with technology/AI. No HQ location, fund details, AUM, check sizes, or specific deal criteria found in provided content. Needs additional sources for complete criteria extraction. | AC7: =COUNTIF(Sheet1!$A$1:$A$50,Firms!A7) -> 0
A8: AFM Capital Partners, Inc. | B8: Other | E8: https://www.afmcap.com | P8: Industrials, Healthcare, Consumer | U8: Active | X8: Low | Y8: Yes | Z8: 2026-06-07 | AA8: complete | AB8: Seeded from CapIQ export. Numeric fields are regex first-pass — crawler will confirm. capiq_description preserved for AI extraction fallback. | [extractor] Portfolio page accessed but contains only HTML/CSS boilerplate and schema markup. No investment criteria, fund details, or portfolio company information extracted. Page shows company name 'AFM Capital Partners' and tagline 'Building Great Companies for Long-term Success'. One portfolio company image reference: Incodema3D. Insufficient data to populate investment criteria. Recommend review of main website pages or criteria document. | AC8: =COUNTIF(Sheet1!$A$1:$A$50,Firms!A8) -> 0
A9: Abacus Global Management, Inc. (NYSE:ABX) | B9: Other | E9: https://abacusgm.com | F9: primarily | O9: Other | P9: Financial Services | T9: 3000.0 | X9: Medium | Y9: No | Z9: 2026-06-07 | AA9: complete | AB9: Seeded from CapIQ export. Numeric fields are regex first-pass — crawler will confirm. capiq_description preserved for AI extraction fallback. | [extractor] Abacus Global Management (NYSE: ABX) is a publicly traded company, not a traditional PE/VC firm. Primary business is acquiring and managing life insurance policies as an alternative asset class via subsidiary Abacus Life Solutions. AUM of ~$3 billion stated on site. Operating in 49 states. Founded 2004. Over $10B in face value of policies purchased. 78 institutional investor partners. HQ city/state not confirmed from content provided. Firm type is closest to 'Other' as it is a publicly listed alternative asset manager focused on life settlements. Deal types do not map cleanly to standard PE/VC categories. Needs review due to non-standard firm classification and ambiguous investment criteria. | AC9: =COUNTIF(Sheet1!$A$1:$A$50,Firms!A9) -> 0
A10: Accel-KKR LLC | B10: PE | C10: CA | D10: Menlo Park | E10: https://www.accel-kkr.com | F10: true | H10: 200.0 | O10: Buyout, Growth Equity, Other | P10: Technology | T10: 21000.0 | U10: Active | X10: Medium | Y10: No | Z10: 2026-06-07 | AA10: complete | AB10: Seeded from CapIQ export. Numeric fields are regex first-pass — crawler will confirm. capiq_description preserved for AI extraction fallback. | [extractor] Accel-KKR is a PE specialist in mid-market software and tech-enabled services. Explicit investment criteria: company revenue up to $200M+, founder-owned or closely-held private companies, structures include buyouts, minority growth capital, corporate carveouts, take-privates, credit investments, and secondaries. Firm has made 500+ software investments over 25 years. Multiple office locations: Menlo Park (HQ), Atlanta, Chicago, London. No specific fund details, AUM, or minimum check size disclosed on the provided page. | AC10: =COUNTIF(Sheet1!$A$1:$A$50,Firms!A10) -> 0
A11: Acorn Growth Companies, LLC | B11: PE | E11: https://www.acorncapitalmanagement.com | F11: true | G11: 30.0 | H11: 200.0 | O11: Buyout | P11: Industrials, Business Services | T11: 893.18 | U11: Active | X11: High | Y11: No | Z11: 2026-06-07 | AA11: complete | AB11: Seeded from CapIQ export. Numeric fields are regex first-pass — crawler will confirm. capiq_description preserved for AI extraction fallback. | [extractor] Investment criteria page describes $30-200M range, strong financial performers, industry-focused opportunities in aerospace, defense, intelligence, and space markets. Firm appears to be Acorn Capital Management (not LLC). HQ location not provided on page. Last modified June 2024 indicates active status. | AC11: =COUNTIF(Sheet1!$A$1:$A$50,Firms!A11) -> 0
A12: Advent International, L.P. | B12: PE | E12: https://www.adventinternational.com | P12: Financial Services, Energy, Industrials | U12: Active | X12: Low | Y12: Yes | Z12: 2026-06-07 | AA12: complete | AB12: Seeded from CapIQ export. Numeric fields are regex first-pass — crawler will confirm. capiq_description preserved for AI extraction fallback. | [extractor] Page is investment strategy landing page with minimal extractable criteria. Schema markup confirms Advent International is a PE firm with five core sectors mentioned but sector names not visible in provided content. No financial metrics, deal sizes, fund details, or HQ location found. Full strategy details likely behind accordions/expandable sections not fully rendered in source. Needs review of complete page HTML or additional sources. | AC12: =COUNTIF(Sheet1!$A$1:$A$50,Firms!A12) -> 0
A13: Afinitas, Inc. | B13: Other | C13: MO | D13: St. Louis | E13: https://www.afinitas.com | X13: Low | Y13: Yes | Z13: 2026-06-07 | AA13: complete | AB13: Seeded from CapIQ export. Numeric fields are regex first-pass — crawler will confirm. capiq_description preserved for AI extraction fallback. | [extractor] Afinitas, Inc. is a manufacturer and distributor of precast concrete equipment, forming systems, and concrete accessories—not a PE/VC firm. The source page describes a commercial equipment company, not an investment fund. No investment criteria, deal types, fund information, or portfolio data present. This appears to be a data extraction error or misfiled company. | AC13: =COUNTIF(Sheet1!$A$1:$A$50,Firms!A13) -> 0
A14: Agellus Capital, LLC | B14: PE | E14: https://www.agellus.com | F14: true | I14: 2.0 | J14: 25.0 | O14: Buyout | P14: Business Services, Consumer, Industrials | S14: discretionaryconsumerservices | T14: 400.0 | U14: Active | V14: 2026-03-01 | W14: Fund I | X14: High | Y14: No | Z14: 2026-06-07 | AA14: complete | AB14: Seeded from CapIQ export. Numeric fields are regex first-pass — crawler will confirm. capiq_description preserved for AI extraction fallback. | [extractor] PE firm focused on essential, non-discretionary services. Platform target: $2-25M EBITDA; add-ons any size. Buy-and-build strategy with focus on fragmented markets. Three key verticals: B2B Services, Non-Discretionary Consumer Services, Supply Chain & Infrastructure. Recent investments: Bluejack (Dec 2024), CompassMSP (Sept 2024), HighGrove (Nov 2025), Titan Restoration (Mar 2026). HQ location not explicitly stated on pages provided. Tearsheet PDF available: https://www.agellus.com/documents/FG/agellus/about/652199_Agellus_Tearsheet_-_Feb_2026_1.pdf | AC14: =COUNTIF(Sheet1!$A$1:$A$50,Firms!A14) -> 1 | AD14: =SUBSTITUTE(AB14,"Seeded from CapIQ export. Numeric fields are regex first-pass — c","C") -> Crawler will confirm. capiq_description preserved for AI extraction fallback. | [extractor] PE firm focused on essential, non-discretionary services. Platform target: $2-25M EBITDA; add-ons any size. Buy-and-build strategy with focus on fragmented markets. Three key verticals: B2B Services, Non-Discretionary Consumer Services, Supply Chain & Infrastructure. Recent investments: Bluejack (Dec 2024), CompassMSP (Sept 2024), HighGrove (Nov 2025), Titan Restoration (Mar 2026). HQ location not explicitly stated on pages provided. Tearsheet PDF available: https://www.agellus.com/documents/FG/agellus/about/652199_Agellus_Tearsheet_-_Feb_2026_1.pdf
A15: Align Capital Partners, LP | B15: PE | C15: TX | D15: Dallas | E15: https://www.aligncp.com | F15: primarily | I15: 3.0 | J15: 15.0 | L15: 150.0 | M15: 20.0 | N15: 60.0 | O15: Buyout | P15: Technology, Business Services, Industrials | T15: 2100.0 | U15: Active | V15: 2026-05-28 | X15: High | Y15: No | Z15: 2026-06-07 | AA15: complete | AB15: Seeded from CapIQ export. Numeric fields are regex first-pass — crawler will confirm. capiq_description preserved for AI extraction fallback. | [extractor] Control-focused PE firm with offices in Cleveland and Dallas. Explicitly targets lower-middle market companies with 3-15mm EBITDA (or >5mm ARR for software). Check sizes 20-60mm hold value. Core criteria: actionable organic growth, recurring revenue, niche leadership, 30%+ gross margins, 15%+ EBITDA margins. North America focus (primarily US). Recent deals through May 2026. PDF overview available at https://aligncp.com/wp-content/uploads/ACP-Firm-Overview.pdf | AC15: =COUNTIF(Sheet1!$A$1:$A$50,Firms!A15) -> 1 | AD15: =SUBSTITUTE(AB15,"Seeded from CapIQ export. Numeric fields are regex first-pass — c","C") -> Crawler will confirm. capiq_description preserved for AI extraction fallback. | [extractor] Control-focused PE firm with offices in Cleveland and Dallas. Explicitly targets lower-middle market companies with 3-15mm EBITDA (or >5mm ARR for software). Check sizes 20-60mm hold value. Core criteria: actionable organic growth, recurring revenue, niche leadership, 30%+ gross margins, 15%+ EBITDA margins. North America focus (primarily US). Recent deals through May 2026. PDF overview available at https://aligncp.com/wp-content/uploads/ACP-Firm-Overview.pdf
A16: Almanac Realty Investors, LLC | B16: PE | E16: https://www.almanacrealty.com | F16: primarily | O16: Growth Equity, Minority | P16: Real Estate, Infrastructure | T16: 6000.0 | U16: Active | W16: Almanac Realty | X16: Medium | Y16: No | Z16: 2026-06-07 | AA16: complete | AB16: Seeded from CapIQ export. Numeric fields are regex first-pass — crawler will confirm. capiq_description preserved for AI extraction fallback. | [extractor] Almanac Realty is a real estate-focused investment platform under Neuberger Berman with $6B+ AUM. Two primary strategies: (1) Entity Level—growth capital investments in mid-sized real estate owners/operators; (2) GP Stakes—minority equity in real estate investment managers. Also manages Real Estate Secondaries ($25B commitments) and Real Estate Private Credit ($37.6B+ invested). 59 transactions since inception, 26 avg years IC experience. Operating since 1996. North American focus. HQ location not explicitly stated on page. | AC16: =COUNTIF(Sheet1!$A$1:$A$50,Firms!A16) -> 0
A17: Altaline Capital Management, LLC | B17: PE | C17: CA | D17: Los Angeles | E17: https://www.altaline.com | F17: true | O17: Buyout | P17: Business Services, Technology, Financial Services | U17: Active | V17: 2026 | X17: Medium | Y17: No | Z17: 2026-06-07 | AA17: complete | AB17: Seeded from CapIQ export. Numeric fields are regex first-pass — crawler will confirm. capiq_description preserved for AI extraction fallback. | [extractor] Specialist PE firm focused on services sector transformation. Portfolio shows recent active investments (2025-2026) across tech-enabled services, business services, and financial services. Explicit focus areas documented on website covering vertical market software, essential services, and niche financial services. HQ: 1925 Century Park East, Suite 1700, Los Angeles, CA 90067. US-focused based on portfolio companies and stated service area focus. | AC17: =COUNTIF(Sheet1!$A$1:$A$50,Firms!A17) -> 0
A18: Altaris, LLC | B18: PE | E18: https://www.altariscap.com | F18: true | O18: Buyout | P18: Healthcare | T18: 9000.0 | U18: Active | X18: Medium | Y18: No | Z18: 2026-06-07 | AA18: complete | AB18: Seeded from CapIQ export. Numeric fields are regex first-pass — crawler will confirm. capiq_description preserved for AI extraction fallback. | [extractor] Altaris is a healthcare-focused PE firm founded in 2003 with $9B+ AUM as of June 2025. Exclusively invests in healthcare industry across three subsectors: medical devices/diagnostics, pharmaceuticals/life sciences, and tech-enabled services. 11 active operating companies cited. Over 50 cumulative investments made. No specific investment size, revenue/EBITDA criteria, or HQ location disclosed on provided pages. US investments confirmed through portfolio companies (Minaris, Sharecare, Solesis). | AC18: =COUNTIF(Sheet1!$A$1:$A$50,Firms!A18) -> 0
A19: Amberjack Capital Partners, L.P. | B19: PE | C19: Texas | D19: Houston | E19: https://www.amberjackcapital.com | F19: true | I19: 4.0 | J19: 20.0 | K19: 20.0 | L19: 175.0 | M19: 20.0 | N19: 75.0 | O19: Buyout | P19: Industrials, Infrastructure, Business Services | T19: 1231.38 | U19: Active | X19: High | Y19: No | Z19: 2026-06-07 | AA19: complete | AB19: Seeded from CapIQ export. Numeric fields are regex first-pass — crawler will confirm. capiq_description preserved for AI extraction fallback. | [extractor] Lower middle-market PE firm focused on critical infrastructure services and industrial end markets. Investment criteria explicitly stated: $4M–$20M target EBITDA, $20M–$175M typical platform enterprise value, $20M–$75M equity investment over life of investment. Conservative leverage approach. Portfolio page references active and realized investments but specific deal details not provided in source pages. | AC19: =COUNTIF(Sheet1!$A$1:$A$50,Firms!A19) -> 1 | AD19: =SUBSTITUTE(AB19,"Seeded from CapIQ export. Numeric fields are regex first-pass — c","C") -> Crawler will confirm. capiq_description preserved for AI extraction fallback. | [extractor] Lower middle-market PE firm focused on critical infrastructure services and industrial end markets. Investment criteria explicitly stated: $4M–$20M target EBITDA, $20M–$175M typical platform enterprise value, $20M–$75M equity investment over life of investment. Conservative leverage approach. Portfolio page references active and realized investments but specific deal details not provided in source pages.
A20: Angeles Equity Partners, LLC | B20: PE | C20: CA | D20: Los Angeles | E20: https://www.angelesequity.com | F20: primarily | I20: 0 | J20: 40.0 | L20: 375.0 | N20: 150.0 | O20: Buyout | P20: Industrials, Business Services | T20: 1203.12 | U20: Active | V20: 2025-11-01 | X20: High | Y20: No | Z20: 2026-06-07 | AA20: complete | AB20: Seeded from CapIQ export. Numeric fields are regex first-pass — crawler will confirm. capiq_description preserved for AI extraction fallback. | [extractor] Control equity PE firm focused on lower middle market industrial businesses. Invests in niche manufacturing, critical industrial services, and specialty distribution. 50%+ ownership required. EBITDA criteria spans unprofitable to $40M. Enterprise value up to $375M. Geography includes US & Canada. Portfolio shows 16 current/exited investments from 2016–2025, demonstrating active deal flow. Most recent investment November 2025. Firm Overview PDF available: https://www.angelesequity.com/s/AEP-Overview-June-2026.pdf — not parsed. Fund details and exact AUM not disclosed on website. | AC20: =COUNTIF(Sheet1!$A$1:$A$50,Firms!A20) -> 1 | AD20: =SUBSTITUTE(AB20,"Seeded from CapIQ export. Numeric fields are regex first-pass — c","C") -> Crawler will confirm. capiq_description preserved for AI extraction fallback. | [extractor] Control equity PE firm focused on lower middle market industrial businesses. Invests in niche manufacturing, critical industrial services, and specialty distribution. 50%+ ownership required. EBITDA criteria spans unprofitable to $40M. Enterprise value up to $375M. Geography includes US & Canada. Portfolio shows 16 current/exited investments from 2016–2025, demonstrating active deal flow. Most recent investment November 2025. Firm Overview PDF available: https://www.angelesequity.com/s/AEP-Overview-June-2026.pdf — not parsed. Fund details and exact AUM not disclosed on website.
A21: Antin Infrastructure Partners SAS (ENXTPA:ANTIN) | B21: PE | E21: https://www.antin-ip.com | F21: primarily | M21: 50.0 | N21: 300.0 | O21: Buyout | P21: Infrastructure, Energy | T21: 39685.34 | U21: Active | X21: High | Y21: No | Z21: 2026-06-07 | AA21: complete | AB21: Seeded from CapIQ export. Numeric fields are regex first-pass — crawler will confirm. capiq_description preserved for AI extraction fallback. | [extractor] Infrastructure PE firm based in France (ENXTPA listing ticker). Multiple fund strategies identified: Flagship, Mid Cap (€50m-300m check sizes), and NextGen. Mid Cap strategy explicitly targets Europe and North America across energy & environment, digital, transport, and social infrastructure sectors. Check sizes converted from EUR to USD using mid-range approximation (€50m≈$54m, €300m≈$325m, presented as 50.0-300.0 reflecting EUR amounts). HQ city not explicitly stated in provided pages. No explicit AUM or recent deal dates found in source material. | AC21: =COUNTIF(Sheet1!$A$1:$A$50,Firms!A21) -> 0
A22: Apollo Global Management, Inc. (NYSE:APO) | B22: PE | E22: https://www.apollo.com/institutional/homepage | F22: true | O22: Buyout | P22: Real Estate, Energy, Infrastructure | T22: 938406.0 | U22: Active | V22: 2025-12-01 | X22: Medium | Y22: No | Z22: 2026-06-07 | AA22: complete | AB22: Seeded from CapIQ export. Numeric fields are regex first-pass — crawler will confirm. capiq_description preserved for AI extraction fallback. | [extractor] Apollo Global Management (NYSE:APO) is a diversified asset manager with PE-focused Real Assets platform. Content confirms investment activity in Real Estate, Infrastructure (control-oriented acquisitions, corporate carveouts in mid-market North America/Europe), and Energy Transition/Renewable Energy. Recent deal noted: $6.5B commitment to Ørsted's Hornsea 3 (Dec 2025). Case studies show $565M InterPark mortgage (2021) and Project Helix NPL acquisition (2018). HQ city/state and specific AUM not provided in source. Confidence Medium due to lack of explicit fund-level details and investment criteria thresholds. | AC22: =COUNTIF(Sheet1!$A$1:$A$50,Firms!A22) -> 1 | AD22: =SUBSTITUTE(AB22,"Seeded from CapIQ export. Numeric fields are regex first-pass — c","C") -> Crawler will confirm. capiq_description preserved for AI extraction fallback. | [extractor] Apollo Global Management (NYSE:APO) is a diversified asset manager with PE-focused Real Assets platform. Content confirms investment activity in Real Estate, Infrastructure (control-oriented acquisitions, corporate carveouts in mid-market North America/Europe), and Energy Transition/Renewable Energy. Recent deal noted: $6.5B commitment to Ørsted's Hornsea 3 (Dec 2025). Case studies show $565M InterPark mortgage (2021) and Project Helix NPL acquisition (2018). HQ city/state and specific AUM not provided in source. Confidence Medium due to lack of explicit fund-level details and investment criteria thresholds.
A23: Appian Way Capital Partners, LLC. | B23: PE | C23: TX | D23: Dallas | E23: https://www.appianwaycap.com | F23: true | G23: 10.0 | H23: 100.0 | I23: 2.0 | J23: 10.0 | M23: 10.0 | N23: 50.0 | O23: Buyout, Growth Equity | P23: Industrials, Business Services | U23: Active | X23: High | Y23: No | Z23: 2026-06-07 | AA23: complete | AB23: Seeded from CapIQ export. Numeric fields are regex first-pass — crawler will confirm. capiq_description preserved for AI extraction fallback. | [extractor] Dallas-based PE firm with explicit investment criteria. Focus on Aerospace & Defense, Manufacturing, and Distribution sectors. Targets US-based companies with $10-100M+ revenue and $2-10M+ EBITDA ($4-8M sweet spot). Invests $10-50M initially with capacity for larger checks. Prefers majority or meaningful minority stakes. Growth-focused with hands-on operational involvement; maintains 5-6 portfolio companies. Portfolio includes Gemco Manufacturing (A&D precision parts) and Integrated Field Solutions (industrial automation). Copyright notice shows 2020 date but website appears current. | AC23: =COUNTIF(Sheet1!$A$1:$A$50,Firms!A23) -> 0
A24: Applied Real Intelligence LLC | B24: Other | E24: https://arivc.com | P24: Energy, Healthcare, Industrials | U24: Active | X24: Low | Y24: Yes | Z24: 2026-06-07 | AA24: complete | AB24: Seeded from CapIQ export. Numeric fields are regex first-pass — crawler will confirm. capiq_description preserved for AI extraction fallback. | [extractor] Page content is primarily HTML/CSS boilerplate and JavaScript code. No investment criteria, fund details, or operational information could be extracted. The firm tagline 'You built it; A.R.I. helps you keep it' suggests post-acquisition services but firm type, geography, investment focus, and deal criteria remain unconfirmed. Full page content review needed or access to additional pages required. | AC24: =COUNTIF(Sheet1!$A$1:$A$50,Firms!A24) -> 0
A25: Ara Partners Group, LLC | B25: Other | E25: https://www.arapartners.com | P25: Energy, Industrials, Consumer | T25: 6600.0 | U25: Active | X25: Low | Y25: Yes | Z25: 2026-06-07 | AA25: complete | AB25: Seeded from CapIQ export. Numeric fields are regex first-pass — crawler will confirm. capiq_description preserved for AI extraction fallback. | [extractor] Source page provided contains only HTML boilerplate, CSS, and structured metadata. No substantive investment criteria, fund details, or operational information present. Full website content not provided. Unable to extract any confirmable data. | AC25: =COUNTIF(Sheet1!$A$1:$A$50,Firms!A25) -> 0
A26: Arcapita Group Holdings Limited | B26: PE | E26: https://www.arcapita.com | F26: primarily | O26: Buyout | P26: Real Estate, Business Services, Industrials | U26: Slowing | X26: Medium | Y26: No | Z26: 2026-06-07 | AA26: complete | AB26: Seeded from CapIQ export. Numeric fields are regex first-pass — crawler will confirm. capiq_description preserved for AI extraction fallback. | [extractor] Arcapita is an active PE investor with diversified portfolio across real estate (industrial logistics, rental housing, data centers), business services, and growth capital (fintech, AI). Significant US and global presence evidenced by active investments. Headquarters location not extracted from provided content. Check size, revenue criteria, and fund-specific details not available on this investments page. | AC26: =COUNTIF(Sheet1!$A$1:$A$50,Firms!A26) -> 0
A27: ArchiMed SAS | B27: PE | E27: https://www.archimed.group | P27: Healthcare | T27: 8676.79 | U27: Active | X27: Medium | Y27: Yes | Z27: 2026-06-07 | AA27: complete | AB27: Seeded from CapIQ export. Numeric fields are regex first-pass — crawler will confirm. capiq_description preserved for AI extraction fallback. | [extractor] ArchiMed SAS is a French PE firm focused on healthcare industries (human, animal, environmental health). Only company portfolio page was provided with minimal criteria details. Missing: HQ location specifics, fund details, investment check sizes, revenue/EBITDA targets, deal types, and US investment focus. Needs review of main investment criteria page or fund documentation. | AC27: =COUNTIF(Sheet1!$A$1:$A$50,Firms!A27) -> 0
A28: Arcline Investment Management LP | B28: PE | E28: https://www.arcline.com | F28: primarily | O28: Buyout | P28: Industrials, Technology, Healthcare | T28: 30000.0 | U28: Active | V28: 2026-03-01 | X28: Medium | Y28: No | Z28: 2026-06-07 | AA28: complete | AB28: Seeded from CapIQ export. Numeric fields are regex first-pass — crawler will confirm. capiq_description preserved for AI extraction fallback. | [extractor] Arcline is a growth-oriented PE firm with $30B AUM focused on building industrial platforms through acquisitions. Portfolio of 160+ acquisitions since 2018 across aerospace & defense, engineered components, critical infrastructure, and test & measurement. Mostly US-focused with some European holdings. Buyout/platform strategy with long-term compounding approach. HQ location not specified on page. | AC28: =COUNTIF(Sheet1!$A$1:$A$50,Firms!A28) -> 0
A29: Arkview Capital, L.P. | B29: PE | C29: Connecticut | D29: Stamford | E29: https://www.arkviewcapital.com | F29: true | O29: Buyout | P29: Business Services, Industrials, Financial Services | U29: Active | X29: Medium | Y29: No | Z29: 2026-06-07 | AA29: complete | AB29: Seeded from CapIQ export. Numeric fields are regex first-pass — crawler will confirm. capiq_description preserved for AI extraction fallback. | [extractor] Arkview Capital founded 2020 by Vijay Mehta and two partners. Invests in overlooked, underutilized assets with focus on three sectors: essential businesses, transportation, and financial services. Demonstrated real estate portfolio (parking facilities) in major US metros (Philadelphia, San Diego, Dallas, New York, Memphis). Prior leadership experience in PE (TPG), investment banking (Morgan Stanley), and asset management (ZBI). All investments appear US-based. Confidence medium due to lack of explicit fund size, check size, EBITDA/revenue targets, or formal investment criteria documentation. | AC29: =COUNTIF(Sheet1!$A$1:$A$50,Firms!A29) -> 0
A30: Arlington Management Employees, LLC | B30: PE | E30: https://arlingtoncap.com | O30: Buyout | P30: Healthcare, Industrials, Consumer | T30: 18194.6 | U30: Active | X30: Medium | Y30: Yes | Z30: 2026-06-07 | AA30: complete | AB30: Seeded from CapIQ export. Numeric fields are regex first-pass — crawler will confirm. capiq_description preserved for AI extraction fallback. | [extractor] Firm name is Arlington Capital Partners (ACP), not Arlington Management Employees LLC as provided. Strategy page indicates PE investment focus on government-regulated industries with domain expertise. Minimal structured criteria data extracted from page source. Full investment criteria not visible in provided content. Requires additional source pages or documentation for complete data extraction. | AC30: =COUNTIF(Sheet1!$A$1:$A$50,Firms!A30) -> 0
A31: Arsenal Capital Management LP | B31: PE | E31: https://www.arsenalcapital.com | P31: Healthcare | T31: 9715.62 | U31: Active | X31: Low | Y31: Yes | Z31: 2026-06-07 | AA31: complete | AB31: Seeded from CapIQ export. Numeric fields are regex first-pass — crawler will confirm. capiq_description preserved for AI extraction fallback. | [extractor] Source page is a portfolio page for Arsenal Capital Management LP showing healthcare investments, but the provided content is primarily CSS/JavaScript code with no readable investment criteria, deal details, or firm information extracted. No headquarters location, fund details, investment size ranges, deal types, or other specific criteria could be confirmed. Requires review of actual firm website homepage or investment criteria documentation. | AC31: =COUNTIF(Sheet1!$A$1:$A$50,Firms!A31) -> 0
A32: Artemis Capital Partners Management Co., LLC | B32: PE | C32: MA | D32: Boston | E32: https://www.artemislp.com | F32: true | O32: Buyout | P32: Industrials, Technology | U32: Active | X32: Medium | Y32: No | Z32: 2026-06-07 | AA32: complete | AB32: Seeded from CapIQ export. Numeric fields are regex first-pass — crawler will confirm. capiq_description preserved for AI extraction fallback. | [extractor] Boston-based PE firm focused on buying and building differentiated manufacturers of Industrial Tech. Explicit focus on control acquisitions (buyouts) of engineered product manufacturers with mission-critical applications. Portfolio includes companies in aerospace, life sciences, defense, and semiconductor sectors. Clear technology focus areas: analytical instruments, RF/microwave, testing & measurement, thermal management, optics & photonics, and diagnostics & discovery. Portfolio shows active investments. No fund-level financial data (AUM, check size, vintage year) found on provided pages. | AC32: =COUNTIF(Sheet1!$A$1:$A$50,Firms!A32) -> 0
A33: Ashe Beach Companies | B33: Fundless Sponsor | E33: https://www.ashebeach.com | F33: true | G33: 10.0 | H33: 50.0 | O33: Buyout | P33: Business Services | X33: High | Y33: No | Z33: 2026-06-07 | AA33: complete | AB33: Seeded from CapIQ export. Numeric fields are regex first-pass — crawler will confirm. capiq_description preserved for AI extraction fallback. | [extractor] Independent sponsor (fundless) focused on lower middle market B2B services buyouts. Revenue range $10M-$50M+, requires 15%+ EBITDA margin, asset light model with recurring revenue. Team led by Cliff Goins IV with 25+ years experience; affiliated with EG Collective network. HQ location not specified on website. | AC33: =COUNTIF(Sheet1!$A$1:$A$50,Firms!A33) -> 0
A34: Astira Capital Partners LP | B34: PE | E34: https://www.astiracp.com | F34: true | O34: Buyout, Growth Equity | P34: Financial Services, Technology, Business Services | T34: 777.32 | U34: Active | V34: 2025 | W34: Astira Capital Partners Fund I LP | X34: Medium | Y34: No | Z34: 2026-06-07 | AA34: complete | AB34: Seeded from CapIQ export. Numeric fields are regex first-pass — crawler will confirm. capiq_description preserved for AI extraction fallback. | [extractor] PE firm explicitly states 'Control Buyout or Significant Minority Growth Capital' investment strategy. Portfolio shows recent deals in 2024-2025 across Financial Services, MarTech, and related verticals. Sector focus: Financial Services & FinTech, Government Services & GovTech, Human Capital Management, IT Services, Marketing Services & MarTech, Risk Management & Compliance. Four portfolio companies identified (Numera, CallRevu, Altus, ConData). Headquarters location not explicitly stated on provided pages. | AC34: =COUNTIF(Sheet1!$A$1:$A$50,Firms!A34) -> 0
A35: Atlas FRM LLC | B35: PE | E35: https://www.atlasholdingsllc.com | F35: true | O35: Buyout, Distressed | P35: Industrials, Business Services, Consumer | T35: 18115.02 | U35: Active | X35: Medium | Y35: No | Z35: 2026-06-07 | AA35: complete | AB35: Seeded from CapIQ export. Numeric fields are regex first-pass — crawler will confirm. capiq_description preserved for AI extraction fallback. | [extractor] Atlas Holdings LLC (not Atlas FRM LLC as specified in query—note name discrepancy). PE firm specializing in buyouts and complex distressed/restructuring situations. Invests in operating companies with operational/financial challenges across 12 specified industrial sectors. Has completed 300+ transactions including bankruptcies, carve-outs, restructurings. UK subsidiary Atlas FRM (UK) Limited noted. No HQ location, AUM, fund vintage, or check size data found. Activity appears active based on website. Confidence medium due to limited financial/fund-specific data. Needs review: firm name mismatch in query. | AC35: =COUNTIF(Sheet1!$A$1:$A$50,Firms!A35) -> 0
A36: Audax Management Company, LLC | B36: PE | E36: https://www.audaxprivateequity.com | F36: primarily | I36: 5.0 | J36: 100.0 | L36: 1000.0 | O36: Buyout | P36: Business Services, Consumer, Healthcare | Q36: Financial Services, Industrials, Technology | T36: 19950.28 | U36: Active | X36: High | Y36: No | Z36: 2026-06-07 | AA36: complete | AB36: Seeded from CapIQ export. Numeric fields are regex first-pass — crawler will confirm. capiq_description preserved for AI extraction fallback. | [extractor] Audax Private Equity firm with Flagship and Origins strategies. Buy & Build approach targeting lower middle market. EBITDA range $5M-$100M, Enterprise Values up to $1B. Portfolio includes US/Canada HQ with operations across five continents. Sectors: Business Services, Consumer, Financial Services, Healthcare, Industrial Services & Technologies, Software & Technology. PDF fact sheet available but binary content not fully parsed. | AC36: =COUNTIF(Sheet1!$A$1:$A$50,Firms!A36) -> 1 | AD36: =SUBSTITUTE(AB36,"Seeded from CapIQ export. Numeric fields are regex first-pass — c","C") -> Crawler will confirm. capiq_description preserved for AI extraction fallback. | [extractor] Audax Private Equity firm with Flagship and Origins strategies. Buy & Build approach targeting lower middle market. EBITDA range $5M-$100M, Enterprise Values up to $1B. Portfolio includes US/Canada HQ with operations across five continents. Sectors: Business Services, Consumer, Financial Services, Healthcare, Industrial Services & Technologies, Software & Technology. PDF fact sheet available but binary content not fully parsed.
A37: Aurelia Capital | B37: Other | E37: https://aureliacap.com | P37: Industrials, Technology | T37: 3520.0 | X37: Low | Y37: Yes | Z37: 2026-06-07 | AA37: complete | AB37: Seeded from CapIQ export. Numeric fields are regex first-pass — crawler will confirm. capiq_description preserved for AI extraction fallback. | [extractor] Source page (https://aureliacap.com/about) contains only CSS/font declarations and no substantive investment criteria data. No firm information, fund details, investment thesis, or financial parameters could be extracted. Requires review of additional pages or documents to populate criteria. | AC37: =COUNTIF(Sheet1!$A$1:$A$50,Firms!A37) -> 0
A38: Aurora Capital Partners | B38: Other | E38: https://www.auroracap.com | P38: Energy, Industrials, Healthcare | T38: 6000.0 | U38: Active | X38: Low | Y38: Yes | Z38: 2026-06-07 | AA38: complete | AB38: Seeded from CapIQ export. Numeric fields are regex first-pass — crawler will confirm. capiq_description preserved for AI extraction fallback. | [extractor] Source page contains only New Relic tracking and analytics code. No investment criteria, fund information, or business details visible. Page at https://www.auroracap.com/Strategy appears to be rendering dynamic content not captured in provided source. | AC38: =COUNTIF(Sheet1!$A$1:$A$50,Firms!A38) -> 0
A39: Author Capital Partners, LLC | B39: PE | C39: IL | D39: Chicago | E39: https://www.authorcapital.com | F39: primarily | I39: 2.0 | J39: 20.0 | M39: 5.0 | N39: 30.0 | O39: Buyout | P39: Generalist | U39: Active | X39: High | Y39: No | Z39: 2026-06-07 | AA39: complete | AB39: Seeded from CapIQ export. Numeric fields are regex first-pass — crawler will confirm. capiq_description preserved for AI extraction fallback. | [extractor] Equity Investment check size $5M-$30M+, EBITDA $2M-$20M confirmed. Invests in US and Canada-based businesses with sustainable competitive advantages and recurring revenue. Focus on family and founder-led businesses with long-term growth prospects. Buy-and-build strategy employed. No fund-specific details, AUM, or recent deal dates found on provided pages. | AC39: =COUNTIF(Sheet1!$A$1:$A$50,Firms!A39) -> 1 | AD39: =SUBSTITUTE(AB39,"Seeded from CapIQ export. Numeric fields are regex first-pass — c","C") -> Crawler will confirm. capiq_description preserved for AI extraction fallback. | [extractor] Equity Investment check size $5M-$30M+, EBITDA $2M-$20M confirmed. Invests in US and Canada-based businesses with sustainable competitive advantages and recurring revenue. Focus on family and founder-led businesses with long-term growth prospects. Buy-and-build strategy employed. No fund-specific details, AUM, or recent deal dates found on provided pages.
A40: Avem Partners | B40: PE | D40: Southern California | E40: https://www.avempartners.com | F40: primarily | G40: 15.0 | H40: 200.0 | I40: 3.0 | K40: 15.0 | L40: 150.0 | M40: 10.0 | N40: 50.0 | O40: Buyout | P40: Industrials | U40: Active | X40: High | Y40: No | Z40: 2026-06-07 | AA40: complete | AB40: Seeded from CapIQ export. Numeric fields are regex first-pass — crawler will confirm. capiq_description preserved for AI extraction fallback. | [extractor] Avem Partners is a PE firm exclusively focused on aerospace/defense lower middle market companies in North America. Founded 2017. Investment criteria explicitly stated: $10-50M check size, $15-150M EV, $15-200M revenue, $3M+ EBITDA. Deal structure involves majority control, limited leverage. HQ stated as 'Southern California' but specific city/state not provided. Multiple realized investments listed (Spencer Aerospace, Synchronous Aerospace Group, Advent Aerospace, Aero Pacific, Drilltec, Resco, Alloy Processing); no unrealized investment details visible on provided pages. | AC40: =COUNTIF(Sheet1!$A$1:$A$50,Firms!A40) -> 1 | AD40: =SUBSTITUTE(AB40,"Seeded from CapIQ export. Numeric fields are regex first-pass — c","C") -> Crawler will confirm. capiq_description preserved for AI extraction fallback. | [extractor] Avem Partners is a PE firm exclusively focused on aerospace/defense lower middle market companies in North America. Founded 2017. Investment criteria explicitly stated: $10-50M check size, $15-150M EV, $15-200M revenue, $3M+ EBITDA. Deal structure involves majority control, limited leverage. HQ stated as 'Southern California' but specific city/state not provided. Multiple realized investments listed (Spencer Aerospace, Synchronous Aerospace Group, Advent Aerospace, Aero Pacific, Drilltec, Resco, Alloy Processing); no unrealized investment details visible on provided pages.
...

Sheet Sheet2
A1: Firm Name | B1: Type | C1: State | D1: City | E1: Website | F1: US Investments | G1: Revenue Min ($M) | H1: Revenue Max ($M) | I1: EBITDA Min ($M) | J1: EBITDA Max ($M) | K1: EV Min ($M) | L1: EV Max ($M) | M1: Check Min ($M) | N1: Check Max ($M) | O1: Deal Types | P1: Sector Tier 1 | Q1: AUM ($M) | R1: Activity | S1: Last Deal | T1: Fund Name | U1: Confidence | V1: Needs Review | W1: Last Checked | X1: Status | Y1: Notes
A2: A&M Capital Advisors, LP | B2: PE | C2: CT | D2: Greenwich | E2: https://www.a-mcapital.com | F2: primarily | I2: 15.0 | J2: 100.0 | K2: 75.0 | L2: 750.0 | M2: 25.0 | N2: 200.0 | O2: Buyout, Recap, Other | P2: Business Services, Healthcare, Industrials | Q2: 5900.0 | R2: Active | U2: High | V2: No | W2: 2026-06-07 | X2: complete | Y2: Crawler will confirm. capiq_description preserved for AI extraction fallback. | [extractor] Multi-strategy PE firm with 4 distinct investment strategies (AMCP, AMCS, AMCE, AMCSI). Data extracted from primary investment criteria sections. AMCP flagship strategy: $3.0B AUM, $60-200M check size, $150-750M target EV, $20-100M EBITDA. AMCS secondaries: $25-75M initial checks, $100-500M EV, $15M+ underlying EBITDA. AMCE (Europe): €650M AUM (~$710M USD). AMCSI: $10-50M checks, $100M+ EV, $20M+ EBITDA. Total firm AUM stated as $5.9B. Transaction types include founder transitions, build-ups, corporate divestitures, public-to-privates, and special situations. Active investor with 170+ companies invested across 24 platforms since inception.
A3: AE Industrial Partners, LP | B3: PE | C3: FL | D3: Boca Raton | E3: https://www.aeroequity.com | F3: true | O3: Buyout, Minority | P3: Industrials, Technology | R3: Active | S3: 2025-06-01 | U3: Medium | V3: No | W3: 2026-06-07 | X3: complete | Y3: Crawler will confirm. capiq_description preserved for AI extraction fallback. | [extractor] AE Industrial Partners is a PE firm focused on aerospace, national security, and industrial services. Founded 2015. 30+ platform companies and 80+ minority/add-on investments completed. Two PDFs available but not parsed: 2025 Year In Review (https://www.aeroequity.com/wp-content/uploads/AE-Industrial-Partners-2025-Year-In-Review.pdf) and Fact Sheet April 2026 (https://www.aeroequity.com/wp-content/uploads/AE-Industrial-Fact-Sheet-April-2026.pdf). Also operates AE Ventures (early-stage tech) and AEI Aerospace Leasing. Additional office in Washington, D.C.
A4: Agellus Capital, LLC | B4: PE | E4: https://www.agellus.com | F4: true | I4: 2.0 | J4: 25.0 | O4: Buyout | P4: Business Services, Consumer, Industrials | Q4: 400.0 | R4: Active | S4: 2026-03-01 | T4: Fund I | U4: High | V4: No | W4: 2026-06-07 | X4: complete | Y4: Crawler will confirm. capiq_description preserved for AI extraction fallback. | [extractor] PE firm focused on essential, non-discretionary services. Platform target: $2-25M EBITDA; add-ons any size. Buy-and-build strategy with focus on fragmented markets. Three key verticals: B2B Services, Non-Discretionary Consumer Services, Supply Chain & Infrastructure. Recent investments: Bluejack (Dec 2024), CompassMSP (Sept 2024), HighGrove (Nov 2025), Titan Restoration (Mar 2026). HQ location not explicitly stated on pages provided. Tearsheet PDF available: https://www.agellus.com/documents/FG/agellus/about/652199_Agellus_Tearsheet_-_Feb_2026_1.pdf
A5: Align Capital Partners, LP | B5: PE | C5: TX | D5: Dallas | E5: https://www.aligncp.com | F5: primarily | I5: 3.0 | J5: 15.0 | L5: 150.0 | M5: 20.0 | N5: 60.0 | O5: Buyout | P5: Technology, Business Services, Industrials | Q5: 2100.0 | R5: Active | S5: 2026-05-28 | U5: High | V5: No | W5: 2026-06-07 | X5: complete | Y5: Crawler will confirm. capiq_description preserved for AI extraction fallback. | [extractor] Control-focused PE firm with offices in Cleveland and Dallas. Explicitly targets lower-middle market companies with 3-15mm EBITDA (or >5mm ARR for software). Check sizes 20-60mm hold value. Core criteria: actionable organic growth, recurring revenue, niche leadership, 30%+ gross margins, 15%+ EBITDA margins. North America focus (primarily US). Recent deals through May 2026. PDF overview available at https://aligncp.com/wp-content/uploads/ACP-Firm-Overview.pdf
A6: Amberjack Capital Partners, L.P. | B6: PE | C6: Texas | D6: Houston | E6: https://www.amberjackcapital.com | F6: true | I6: 4.0 | J6: 20.0 | K6: 20.0 | L6: 175.0 | M6: 20.0 | N6: 75.0 | O6: Buyout | P6: Industrials, Infrastructure, Business Services | Q6: 1231.38 | R6: Active | U6: High | V6: No | W6: 2026-06-07 | X6: complete | Y6: Crawler will confirm. capiq_description preserved for AI extraction fallback. | [extractor] Lower middle-market PE firm focused on critical infrastructure services and industrial end markets. Investment criteria explicitly stated: $4M–$20M target EBITDA, $20M–$175M typical platform enterprise value, $20M–$75M equity investment over life of investment. Conservative leverage approach. Portfolio page references active and realized investments but specific deal details not provided in source pages.
A7: Angeles Equity Partners, LLC | B7: PE | C7: CA | D7: Los Angeles | E7: https://www.angelesequity.com | F7: primarily | I7: 0 | J7: 40.0 | L7: 375.0 | N7: 150.0 | O7: Buyout | P7: Industrials, Business Services | Q7: 1203.12 | R7: Active | S7: 2025-11-01 | U7: High | V7: No | W7: 2026-06-07 | X7: complete | Y7: Crawler will confirm. capiq_description preserved for AI extraction fallback. | [extractor] Control equity PE firm focused on lower middle market industrial businesses. Invests in niche manufacturing, critical industrial services, and specialty distribution. 50%+ ownership required. EBITDA criteria spans unprofitable to $40M. Enterprise value up to $375M. Geography includes US & Canada. Portfolio shows 16 current/exited investments from 2016–2025, demonstrating active deal flow. Most recent investment November 2025. Firm Overview PDF available: https://www.angelesequity.com/s/AEP-Overview-June-2026.pdf — not parsed. Fund details and exact AUM not disclosed on website.
A8: Apollo Global Management, Inc. (NYSE:APO) | B8: PE | E8: https://www.apollo.com/institutional/homepage | F8: true | O8: Buyout | P8: Real Estate, Energy, Infrastructure | Q8: 938406.0 | R8: Active | S8: 2025-12-01 | U8: Medium | V8: No | W8: 2026-06-07 | X8: complete | Y8: Crawler will confirm. capiq_description preserved for AI extraction fallback. | [extractor] Apollo Global Management (NYSE:APO) is a diversified asset manager with PE-focused Real Assets platform. Content confirms investment activity in Real Estate, Infrastructure (control-oriented acquisitions, corporate carveouts in mid-market North America/Europe), and Energy Transition/Renewable Energy. Recent deal noted: $6.5B commitment to Ørsted's Hornsea 3 (Dec 2025). Case studies show $565M InterPark mortgage (2021) and Project Helix NPL acquisition (2018). HQ city/state and specific AUM not provided in source. Confidence Medium due to lack of explicit fund-level details and investment criteria thresholds.
A9: Audax Management Company, LLC | B9: PE | E9: https://www.audaxprivateequity.com | F9: primarily | I9: 5.0 | J9: 100.0 | L9: 1000.0 | O9: Buyout | P9: Business Services, Consumer, Healthcare | Q9: 19950.28 | R9: Active | U9: High | V9: No | W9: 2026-06-07 | X9: complete | Y9: Crawler will confirm. capiq_description preserved for AI extraction fallback. | [extractor] Audax Private Equity firm with Flagship and Origins strategies. Buy & Build approach targeting lower middle market. EBITDA range $5M-$100M, Enterprise Values up to $1B. Portfolio includes US/Canada HQ with operations across five continents. Sectors: Business Services, Consumer, Financial Services, Healthcare, Industrial Services & Technologies, Software & Technology. PDF fact sheet available but binary content not fully parsed.
A10: Author Capital Partners, LLC | B10: PE | C10: IL | D10: Chicago | E10: https://www.authorcapital.com | F10: primarily | I10: 2.0 | J10: 20.0 | M10: 5.0 | N10: 30.0 | O10: Buyout | P10: Generalist | R10: Active | U10: High | V10: No | W10: 2026-06-07 | X10: complete | Y10: Crawler will confirm. capiq_description preserved for AI extraction fallback. | [extractor] Equity Investment check size $5M-$30M+, EBITDA $2M-$20M confirmed. Invests in US and Canada-based businesses with sustainable competitive advantages and recurring revenue. Focus on family and founder-led businesses with long-term growth prospects. Buy-and-build strategy employed. No fund-specific details, AUM, or recent deal dates found on provided pages.
A11: Avem Partners | B11: PE | D11: Southern California | E11: https://www.avempartners.com | F11: primarily | G11: 15.0 | H11: 200.0 | I11: 3.0 | K11: 15.0 | L11: 150.0 | M11: 10.0 | N11: 50.0 | O11: Buyout | P11: Industrials | R11: Active | U11: High | V11: No | W11: 2026-06-07 | X11: complete | Y11: Crawler will confirm. capiq_description preserved for AI extraction fallback. | [extractor] Avem Partners is a PE firm exclusively focused on aerospace/defense lower middle market companies in North America. Founded 2017. Investment criteria explicitly stated: $10-50M check size, $15-150M EV, $15-200M revenue, $3M+ EBITDA. Deal structure involves majority control, limited leverage. HQ stated as 'Southern California' but specific city/state not provided. Multiple realized investments listed (Spencer Aerospace, Synchronous Aerospace Group, Advent Aerospace, Aero Pacific, Drilltec, Resco, Alloy Processing); no unrealized investment details visible on provided pages.
A12: Bain Capital, LP | B12: PE | C12: MA | D12: Boston | E12: https://www.baincapital.com | F12: true | O12: Buyout, Growth Equity, Venture | P12: Generalist | Q12: 215000.0 | R12: Active | S12: 2026-06-07 | U12: Medium | V12: No | W12: 2026-06-07 | X12: complete | Y12: Crawler will confirm. capiq_description preserved for AI extraction fallback. | [extractor] Bain Capital is a diversified global investment firm with multiple platforms: Private Equity (Global PE, Double Impact, Insurance), Growth & Venture (Ventures, Life Sciences, Tech Opportunities, Crypto), Capital Solutions (Special Situations), Credit, and Real Assets (Real Estate). Founded 1984, headquartered Boston. Recent deal activity confirmed (Asia Fund VI close June 2026, $10.5B raised). AUM figure listed as ~$0B on page (appears to be placeholder). Specific investment criteria, check sizes, and sector preferences not provided on this page. Multi-platform structure suggests Generalist approach. needs_review=true due to incomplete AUM data and lack of specific criteria details.
A13: Balmoral Funds LLC | B13: PE | C13: CA | D13: Los Angeles | E13: https://www.balmoralfunds.com | F13: true | G13: 30.0 | H13: 800.0 | M13: 10.0 | N13: 100.0 | O13: Buyout, Recap | P13: Industrials, Business Services, Consumer | Q13: 1300.0 | R13: Active | S13: 2025-12-09 | U13: High | V13: No | W13: 2026-06-07 | X13: complete | Y13: Crawler will confirm. capiq_description preserved for AI extraction fallback. | [extractor] Special situations PE firm focused on control and shared-control investments. Investment criteria explicitly stated on website. Portfolio includes diversified industrial, logistics, and specialty manufacturing companies. Recent deals through December 2025. Fact sheet PDF available at https://www.balmoralfunds.com/wp-content/uploads/Balmoral-Fact-Sheet-03-23-2026.pdf but not parsed. Sectors inferred from portfolio companies (aviation, logistics, modular construction, specialty chemicals). No AUM, fund vintage, or explicit sector exclusions disclosed.
A14: Blackstone Inc. (NYSE:BX) | B14: PE | E14: https://www.blackstone.com | O14: Buyout | P14: Real Estate, Infrastructure, Generalist | Q14: 1274931.23 | R14: Active | U14: Medium | V14: No | W14: 2026-06-07 | X14: complete | Y14: Crawler will confirm. capiq_description preserved for AI extraction fallback. | [extractor] Blackstone is a publicly traded diversified alternative asset manager (NYSE:BX) with multiple business lines including Private Equity, Real Estate, Credit & Insurance, Infrastructure, Life Sciences, Growth, and Energy Transition Partners. Website is corporate overview; specific investment criteria not detailed. HQ location not confirmed from provided content. AUM and specific fund information not extracted from homepage. Requires review of individual business unit pages or investor materials for detailed criteria.
A15: Blue Sage Capital, L.P. | B15: PE | C15: TX | D15: Austin | E15: https://www.bluesage.com | F15: true | I15: 5.0 | J15: 25.0 | M15: 25.0 | N15: 60.0 | O15: Buyout, Growth Equity, Recap, Mezzanine | P15: Industrials, Business Services | Q15: 1000.0 | R15: Active | S15: 2025-11-05 | T15: Blue Sage Capital IV, L.P. | U15: High | V15: No | W15: 2026-06-07 | X15: complete | Y15: Crawler will confirm. capiq_description preserved for AI extraction fallback. | [extractor] Firm at a Glance PDF available: https://static.spacecrafted.com/c92111026fa443e6b8fe2553197229b3/r/e47e0544e59d424198110dd6cbf5f238/1/Blue%20Sage%20Flyer%20%28%20October%20-%2025%29.pdf — not parsed. AUM stated as 'over a billion dollars' set to 1000.0. Fund IV closed January 2025 at $618M; Blue Sage Strategic Credit Fund closed October 2025 at $287M. Recent deal activity through November 2025 indicates Active status. Check size range inferred from '$25-60M investment' language. Sector keywords extracted from stated industries. Deal types include majority/minority equity and mezzanine debt flexibility per criteria.
A16: Borgman Capital LLC | B16: PE | C16: IL | D16: Chicago | E16: https://www.borgmancapital.com | F16: primarily | G16: 10.0 | H16: 75.0 | I16: 2.0 | J16: 10.0 | K16: 15.0 | L16: 100.0 | M16: 5.0 | N16: 30.0 | O16: Buyout, Recap | P16: Industrials, Business Services, Healthcare | R16: Active | U16: High | V16: No | W16: 2026-06-04 | X16: complete | Y16: Crawler will confirm. capiq_description preserved for AI extraction fallback. | [crawler] Explicit investment criteria page found.
A17: Brodie Generational Capital Partners, LLC | B17: Family Office | C17: PA | D17: Radnor | E17: https://bgencap.com | F17: primarily | G17: 100.0 | I17: 20.0 | J17: 50.0 | K17: 150.0 | L17: 500.0 | O17: Buyout | P17: Industrials, Healthcare | U17: High | V17: No | W17: 2026-06-07 | X17: complete | Y17: Crawler will confirm. capiq_description preserved for AI extraction fallback. | [extractor] Family-owned investment firm investing own capital. Focuses on control acquisitions (buyout) of established middle-market businesses in industrial/manufacturing sectors. Explicit criteria: US or UK HQ, revenue $100M+, EBITDA $20-50M, deal size $150-500M, B2B distribution, family-owned preference, control position required. Portfolio includes Sur-Seal and Zahav Bioscience. No fund structure identified; appears to be evergreen family office vehicle.
